<?xml version="1.0"?>
<!-- created with Phobos 1.0.1 "Capricious Choutengan" -->
<robot name="fingers" xmlns:xacro="http://wiki.ros.org/xacro">
  <xacro:macro name="fingers" params="name y lower_limit upper_limit">
    <link name="${name}_link">
      <collision name="${name}_collision">
        <origin rpy="0.00000 0.00000 0.00000" xyz="0.00000 0.00000 -0.00000"/>
        <geometry>
          <box size="0.40000 0.10000 0.30000"/>
        </geometry>
      </collision>
      <inertial>
        <inertia ixx="0.02500" ixy="0.00000" ixz="0.00000" iyy="0.06250" iyz="0.00000" izz="0.04250"/>
        <origin rpy="0.00000 0.00000 0.00000" xyz="0.00000 0.00000 0.00000"/>
        <mass value="3.00000"/>
      </inertial>
      <visual name="${name}">
        <origin rpy="0.00000 0.00000 0.00000" xyz="0.00000 0.00000 -0.00000"/>
        <material name="Black"/>
        <geometry>
          <box size="0.40000 0.10000 0.30000"/>
        </geometry>
      </visual>
    </link>

    <joint name="${name}_link_joint" type="prismatic">
      <limit lower="${lower_limit}" upper="${upper_limit}" effort="100000.00000" velocity="100000.00000"/>
      <origin rpy="0.00000 0.00000 0.00000" xyz="-0.00000 ${y} -0.20000"/>
      <parent link="Arm_Hand_link"/>
      <child link="${name}_link"/>
      <axis xyz="0.00000 1.00000 0.00000"/>
    </joint>

  </xacro:macro>
</robot>